<?xml version="1.0"?>
<robot name="robomesh_three_link_capsule">
  <link name="base_link">
    <visual>
      <origin xyz="0 0 0" rpy="0 0 0"/>
      <geometry>
        <box size="0.18 0.18 0.04"/>
      </geometry>
      <material name="base_gray">
        <color rgba="0.55 0.55 0.55 1"/>
      </material>
    </visual>
  </link>

  <link name="upper_link">
    <!-- Capsule: radius 0.025, length 0.28 -->
    <visual>
      <origin xyz="0 0 0.14" rpy="0 0 0"/>
      <geometry>
        <cylinder radius="0.025" length="0.23"/>
      </geometry>
      <material name="blue">
        <color rgba="0.2 0.4 0.85 1"/>
      </material>
    </visual>
    <visual>
      <origin xyz="0 0 0.025" rpy="0 0 0"/>
      <geometry>
        <sphere radius="0.025"/>
      </geometry>
      <material name="blue"/>
    </visual>
    <visual>
      <origin xyz="0 0 0.255" rpy="0 0 0"/>
      <geometry>
        <sphere radius="0.025"/>
      </geometry>
      <material name="blue"/>
    </visual>
  </link>

  <link name="forearm_link">
    <!-- Capsule: radius 0.022, length 0.24 -->
    <visual>
      <origin xyz="0 0 0.12" rpy="0 0 0"/>
      <geometry>
        <cylinder radius="0.022" length="0.196"/>
      </geometry>
      <material name="orange">
        <color rgba="0.95 0.55 0.25 1"/>
      </material>
    </visual>
    <visual>
      <origin xyz="0 0 0.022" rpy="0 0 0"/>
      <geometry>
        <sphere radius="0.022"/>
      </geometry>
      <material name="orange"/>
    </visual>
    <visual>
      <origin xyz="0 0 0.218" rpy="0 0 0"/>
      <geometry>
        <sphere radius="0.022"/>
      </geometry>
      <material name="orange"/>
    </visual>
  </link>

  <link name="wrist_link">
    <!-- Capsule: radius 0.02, length 0.18 -->
    <visual>
      <origin xyz="0 0 0.09" rpy="0 0 0"/>
      <geometry>
        <cylinder radius="0.02" length="0.14"/>
      </geometry>
      <material name="green">
        <color rgba="0.2 0.75 0.4 1"/>
      </material>
    </visual>
    <visual>
      <origin xyz="0 0 0.02" rpy="0 0 0"/>
      <geometry>
        <sphere radius="0.02"/>
      </geometry>
      <material name="green"/>
    </visual>
    <visual>
      <origin xyz="0 0 0.16" rpy="0 0 0"/>
      <geometry>
        <sphere radius="0.02"/>
      </geometry>
      <material name="green"/>
    </visual>
  </link>

  <link name="hand_link">
    <visual>
      <origin xyz="0 0 0.02" rpy="0 0 0"/>
      <geometry>
        <sphere radius="0.022"/>
      </geometry>
      <material name="hand">
        <color rgba="0.95 0.95 0.95 1"/>
      </material>
    </visual>
  </link>

  <joint name="shoulder" type="revolute">
    <origin xyz="0 0 0" rpy="0 0 0"/>
    <parent link="base_link"/>
    <child link="upper_link"/>
    <axis xyz="0 1 0"/>
    <limit lower="-3.14" upper="3.14" effort="1" velocity="1"/>
  </joint>

  <joint name="elbow" type="revolute">
    <origin xyz="0 0 0.28" rpy="0 0 0"/>
    <parent link="upper_link"/>
    <child link="forearm_link"/>
    <axis xyz="0 1 0"/>
    <limit lower="-3.14" upper="3.14" effort="1" velocity="1"/>
  </joint>

  <joint name="wrist" type="revolute">
    <origin xyz="0 0 0.24" rpy="0 0 0"/>
    <parent link="forearm_link"/>
    <child link="wrist_link"/>
    <axis xyz="0 1 0"/>
    <limit lower="-3.14" upper="3.14" effort="1" velocity="1"/>
  </joint>

  <joint name="tool_mount" type="fixed">
    <origin xyz="0 0 0.18" rpy="0 0 0"/>
    <parent link="wrist_link"/>
    <child link="hand_link"/>
  </joint>
</robot>
